Workbook

Sheet Matriz
A1: HomeScope — Matriz de roles y permisos
A2: Sí = permitido · Propio = solo sobre sus propios recursos · Condicional = permitido si se cumple la condición indicada · No = no permitido. Ver la hoja "Leyenda y reglas".
A4: Módulo | B4: Código del permiso | C4: Descripción | D4: Visitante (sin sesión) | E4: Comprador | F4: Vendedor | G4: Administrador | H4: Condición / regla de negocio | I4: Requerimiento
A5: Cuenta y perfil | B5: cuenta.registrar | C5: Crear una cuenta como comprador, vendedor o ambos | D5: Sí | E5: No | F5: No | G5: No | H5: Solo sin sesión iniciada. El rol de administrador nunca se elige en el registro. | I5: RF-01 · HU-06
A6: Cuenta y perfil | B6: cuenta.iniciar_sesion | C6: Iniciar sesión y usar "recordar sesión" | D6: Sí | E6: No | F6: No | G6: No | H6: La cuenta debe estar activa (no suspendida ni inhabilitada). | I6: RF-03 · HU-07
A7: Cuenta y perfil | B7: cuenta.recuperar_password | C7: Solicitar recuperación de contraseña por correo | D7: Sí | E7: No | F7: No | G7: No | H7: El enlace expira y sirve una sola vez. | I7: RF-04 · HU-07
A8: Cuenta y perfil | B8: cuenta.verificar_correo | C8: Confirmar el correo con el enlace recibido | D8: Sí | E8: Sí | F8: Sí | G8: No | H8: El enlace expira y sirve una sola vez. | I8: RF-02 · HU-06
A9: Cuenta y perfil | B9: cuenta.activar_rol_vendedor | C9: Agregar el rol de vendedor a una cuenta de comprador | D9: No | E9: Sí | F9: No | G9: No | H9: No crea una cuenta nueva; se agrega el rol en UsuarioRol. | I9: RF-01 · T02
A10: Cuenta y perfil | B10: perfil.ver_propio | C10: Ver el propio perfil | D10: No | E10: Sí | F10: Sí | G10: Sí | I10: RF-06 · HU-08
A11: Cuenta y perfil | B11: perfil.editar_propio | C11: Editar los datos del propio perfil | D11: No | E11: Sí | F11: Sí | G11: Sí | H11: Cambiar la contraseña invalida las sesiones recordadas. | I11: RF-06 · HU-08
A12: Cuenta y perfil | B12: perfil.ver_publico | C12: Ver el perfil público de un vendedor (reseñas, insignia) | D12: Sí | E12: Sí | F12: Sí | G12: Sí | H12: Nunca muestra teléfono ni correo. | I12: RF-27, RF-30
A13: Cuenta y perfil | B13: perfil.ver_contacto | C13: Ver teléfono y correo de otro usuario | D13: No | E13: Condicional | F13: Condicional | G13: Sí | H13: Solo si existe una conversación entre ambos usuarios. | I13: RF-05, RNF-08 · T48
A14: Cuenta y perfil | B14: historial.ver_propio | C14: Ver el historial propio (vistas, guardadas o publicadas) | D14: No | E14: Propio | F14: Propio | G14: No | H14: El comprador ve vistas y guardadas; el vendedor, sus publicadas. | I14: RF-06 · HU-08
A15: Propiedades | B15: propiedad.ver_catalogo | C15: Ver el catálogo de propiedades publicadas | D15: Sí | E15: Sí | F15: Sí | G15: Sí | H15: Solo propiedades en estado publicado; el administrador ve todas. | I15: RF-18 · T23
A16: Propiedades | B16: propiedad.ver_ficha | C16: Ver la ficha completa de una propiedad | D16: Sí | E16: Sí | F16: Sí | G16: Sí | H16: Pausadas y borradores solo las ve su dueño y el administrador. | I16: RF-07 · HU-09
A17: Propiedades | B17: propiedad.crear | C17: Crear y guardar un borrador de propiedad | D17: No | E17: No | F17: Sí | G17: No | I17: RF-07 · HU-09
A18: Propiedades | B18: propiedad.publicar | C18: Publicar una propiedad | D18: No | E18: No | F18: Condicional | G18: No | H18: Requiere correo verificado y verificación de vendedor aprobada. | I18: RF-02, RF-25 · HU-28
A19: Propiedades | B19: propiedad.editar | C19: Editar datos, precio y ubicación | D19: No | E19: No | F19: Propio | G19: No | H19: Solo el dueño. Cambiar el precio registra historial; cambiar la ubicación recalcula el índice. | I19: RF-10 · HU-10
A20: Propiedades | B20: propiedad.cambiar_estado | C20: Pausar, reactivar o marcar como vendida/alquilada | D20: No | E20: No | F20: Propio | G20: No | H20: Solo el dueño. El administrador pausa mediante moderación. | I20: RF-10 · HU-10
A21: Propiedades | B21: propiedad.renovar | C21: Renovar un anuncio próximo a expirar | D21: No | E21: No | F21: Propio | G21: No | H21: Solo el dueño. | I21: RF-10
A22: Propiedades | B22: propiedad.eliminar | C22: Eliminar una propiedad propia | D22: No | E22: No | F22: Propio | G22: No | H22: Solo el dueño. El administrador elimina mediante moderación. | I22: RF-10 · HU-10
A23: Propiedades | B23: foto.gestionar | C23: Subir, ordenar, eliminar fotos y elegir portada | D23: No | E23: No | F23: Propio | G23: No | H23: Solo el dueño. Tamaño y formato validados. | I23: RF-08 · HU-11
A24: Propiedades | B24: precio.ver_historial | C24: Ver la línea de tiempo de precios | D24: Sí | E24: Sí | F24: Sí | G24: Sí | I24: RF-31 · HU-26
A25: Mapa e índice | B25: mapa.ver | C25: Ver mapa, vista satelital y Street View | D25: Sí | E25: Sí | F25: Sí | G25: Sí | I25: RF-09, RF-11 · HU-13
A26: Mapa e índice | B26: poi.ver | C26: Ver puntos de interés, radio y filtro de categorías | D26: Sí | E26: Sí | F26: Sí | G26: Sí | I26: RF-12 a RF-14 · HU-14, HU-15
A27: Mapa e índice | B27: indice.ver | C27: Ver el Índice de Conveniencia y su desglose | D27: Sí | E27: Sí | F27: Sí | G27: Sí | I27: RF-15, RF-16 · HU-18
A28: Mapa e índice | B28: indice.recalcular | C28: Forzar el recálculo del índice | D28: No | E28: No | F28: No | G28: Sí | H28: El sistema recalcula solo al publicar o cambiar la ubicación; el manual es para cambios de pesos. | I28: RF-17, RNF-13
A29: Mapa e índice | B29: indice.configurar_pesos | C29: Modificar categorías y pesos del algoritmo | D29: No | E29: No | F29: No | G29: Sí | H29: Todo cambio incrementa la versión del algoritmo. | I29: RNF-13 · HU-16
A30: Búsqueda y favoritos | B30: busqueda.usar | C30: Buscar por texto y filtros combinables | D30: Sí | E30: Sí | F30: Sí | G30: Sí | I30: RF-18 · HU-20
A31: Búsqueda y favoritos | B31: busqueda.mapa | C31: Buscar directamente sobre el mapa | D31: Sí | E31: Sí | F31: Sí | G31: Sí | I31: RF-19 · HU-21
A32: Búsqueda y favoritos | B32: favorito.gestionar | C32: Guardar y quitar favoritos | D32: No | E32: Propio | F32: No | G32: No | H32: Solo sus propios favoritos. | I32: RF-20 · HU-22
A33: Búsqueda y favoritos | B33: comparador.usar | C33: Comparar hasta 3 favoritos | D33: No | E33: Propio | F33: No | G33: No | H33: Solo entre sus propios favoritos. | I33: RF-20 · HU-22
A34: Búsqueda y favoritos | B34: busqueda.guardar_alerta | C34: Guardar una búsqueda y recibir alertas por correo | D34: No | E34: Propio | F34: No | G34: No | H34: Pendiente: RF-28 no tiene HU ni tarea asignada. | I34: RF-28
A35: Mensajería | B35: conversacion.iniciar | C35: Iniciar una conversación con el vendedor de una propiedad | D35: No | E35: Condicional | F35: No | G35: No | H35: Una por propiedad; no puede ser sobre una propiedad propia. | I35: RF-21 · HU-23
A36: Mensajería | B36: mensaje.enviar | C36: Enviar mensajes en una conversación | D36: No | E36: Condicional | F36: Condicional | G36: No | H36: Solo si participa en la conversación. Con rate limiting. | I36: RF-21, RNF-07 · HU-23
A37: Mensajería | B37: conversacion.ver_propias | C37: Ver sus conversaciones e historial | D37: No | E37: Propio | F37: Propio | G37: No | H37: Solo las conversaciones en las que participa. | I37: RF-23 · HU-23
A38: Mensajería | B38: notificacion.ver_propias | C38: Ver y marcar como leídas sus notificaciones | D38: No | E38: Propio | F38: Propio | G38: Propio | I38: RF-22, RF-28
A39: Agenda de visitas | B39: disponibilidad.gestionar | C39: Definir horarios disponibles para visitas | D39: No | E39: No | F39: Propio | G39: No | H39: Solo su propia disponibilidad; sin franjas superpuestas. | I39: RF-29 · HU-24
A40: Agenda de visitas | B40: visita.solicitar | C40: Solicitar una visita en un horario disponible | D40: No | E40: Condicional | F40: No | G40: No | H40: Dentro de la disponibilidad del vendedor y sin choque con otra visita. | I40: RF-29 · HU-24B
A41: Agenda de visitas | B41: visita.confirmar | C41: Confirmar o reprogramar una visita | D41: No | E41: No | F41: Propio | G41: No | H41: Solo visitas a sus propiedades. | I41: RF-29 · HU-24
...

Sheet Resumen
A1: Resumen de permisos por rol
A3: Nivel de acceso | B3: Visitante (sin sesión) | C3: Comprador | D3: Vendedor | E3: Administrador
A4: Sí | B4: =COUNTIF(Matriz!D$5:D$59,$A4) -> 15 | C4: =COUNTIF(Matriz!E$5:E$59,$A4) -> 16 | D4: =COUNTIF(Matriz!F$5:F$59,$A4) -> 17 | E4: =COUNTIF(Matriz!G$5:G$59,$A4) -> 25
A5: Propio | B5: =COUNTIF(Matriz!D$5:D$59,$A5) -> 0 | C5: =COUNTIF(Matriz!E$5:E$59,$A5) -> 8 | D5: =COUNTIF(Matriz!F$5:F$59,$A5) -> 13 | E5: =COUNTIF(Matriz!G$5:G$59,$A5) -> 1
A6: Condicional | B6: =COUNTIF(Matriz!D$5:D$59,$A6) -> 0 | C6: =COUNTIF(Matriz!E$5:E$59,$A6) -> 6 | D6: =COUNTIF(Matriz!F$5:F$59,$A6) -> 3 | E6: =COUNTIF(Matriz!G$5:G$59,$A6) -> 0
A7: No | B7: =COUNTIF(Matriz!D$5:D$59,$A7) -> 40 | C7: =COUNTIF(Matriz!E$5:E$59,$A7) -> 25 | D7: =COUNTIF(Matriz!F$5:F$59,$A7) -> 22 | E7: =COUNTIF(Matriz!G$5:G$59,$A7) -> 29
A8: Total con algún acceso | B8: =SUM(B4:B6) -> 15 | C8: =SUM(C4:C6) -> 30 | D8: =SUM(D4:D6) -> 33 | E8: =SUM(E4:E6) -> 26
A9: Total de permisos | B9: =SUM(B4:B7) -> 55 | C9: =SUM(C4:C7) -> 55 | D9: =SUM(D4:D7) -> 55 | E9: =SUM(E4:E7) -> 55
A12: Permisos con algún acceso, por módulo
A13: Módulo | B13: Visitante (sin sesión) | C13: Comprador | D13: Vendedor | E13: Administrador | F13: Permisos del módulo
A14: Cuenta y perfil | B14: =COUNTIFS(Matriz!$A$5:$A$59,$A14,Matriz!D$5:D$59,"<>No") -> 5 | C14: =COUNTIFS(Matriz!$A$5:$A$59,$A14,Matriz!E$5:E$59,"<>No") -> 7 | D14: =COUNTIFS(Matriz!$A$5:$A$59,$A14,Matriz!F$5:F$59,"<>No") -> 6 | E14: =COUNTIFS(Matriz!$A$5:$A$59,$A14,Matriz!G$5:G$59,"<>No") -> 4 | F14: =COUNTIF(Matriz!$A$5:$A$59,$A14) -> 10
A15: Propiedades | B15: =COUNTIFS(Matriz!$A$5:$A$59,$A15,Matriz!D$5:D$59,"<>No") -> 3 | C15: =COUNTIFS(Matriz!$A$5:$A$59,$A15,Matriz!E$5:E$59,"<>No") -> 3 | D15: =COUNTIFS(Matriz!$A$5:$A$59,$A15,Matriz!F$5:F$59,"<>No") -> 10 | E15: =COUNTIFS(Matriz!$A$5:$A$59,$A15,Matriz!G$5:G$59,"<>No") -> 3 | F15: =COUNTIF(Matriz!$A$5:$A$59,$A15) -> 10
A16: Mapa e índice | B16: =COUNTIFS(Matriz!$A$5:$A$59,$A16,Matriz!D$5:D$59,"<>No") -> 3 | C16: =COUNTIFS(Matriz!$A$5:$A$59,$A16,Matriz!E$5:E$59,"<>No") -> 3 | D16: =COUNTIFS(Matriz!$A$5:$A$59,$A16,Matriz!F$5:F$59,"<>No") -> 3 | E16: =COUNTIFS(Matriz!$A$5:$A$59,$A16,Matriz!G$5:G$59,"<>No") -> 5 | F16: =COUNTIF(Matriz!$A$5:$A$59,$A16) -> 5
A17: Búsqueda y favoritos | B17: =COUNTIFS(Matriz!$A$5:$A$59,$A17,Matriz!D$5:D$59,"<>No") -> 2 | C17: =COUNTIFS(Matriz!$A$5:$A$59,$A17,Matriz!E$5:E$59,"<>No") -> 5 | D17: =COUNTIFS(Matriz!$A$5:$A$59,$A17,Matriz!F$5:F$59,"<>No") -> 2 | E17: =COUNTIFS(Matriz!$A$5:$A$59,$A17,Matriz!G$5:G$59,"<>No") -> 2 | F17: =COUNTIF(Matriz!$A$5:$A$59,$A17) -> 5
A18: Mensajería | B18: =COUNTIFS(Matriz!$A$5:$A$59,$A18,Matriz!D$5:D$59,"<>No") -> 0 | C18: =COUNTIFS(Matriz!$A$5:$A$59,$A18,Matriz!E$5:E$59,"<>No") -> 4 | D18: =COUNTIFS(Matriz!$A$5:$A$59,$A18,Matriz!F$5:F$59,"<>No") -> 3 | E18: =COUNTIFS(Matriz!$A$5:$A$59,$A18,Matriz!G$5:G$59,"<>No") -> 1 | F18: =COUNTIF(Matriz!$A$5:$A$59,$A18) -> 4
A19: Agenda de visitas | B19: =COUNTIFS(Matriz!$A$5:$A$59,$A19,Matriz!D$5:D$59,"<>No") -> 0 | C19: =COUNTIFS(Matriz!$A$5:$A$59,$A19,Matriz!E$5:E$59,"<>No") -> 3 | D19: =COUNTIFS(Matriz!$A$5:$A$59,$A19,Matriz!F$5:F$59,"<>No") -> 4 | E19: =COUNTIFS(Matriz!$A$5:$A$59,$A19,Matriz!G$5:G$59,"<>No") -> 0 | F19: =COUNTIF(Matriz!$A$5:$A$59,$A19) -> 5
A20: Reputación | B20: =COUNTIFS(Matriz!$A$5:$A$59,$A20,Matriz!D$5:D$59,"<>No") -> 2 | C20: =COUNTIFS(Matriz!$A$5:$A$59,$A20,Matriz!E$5:E$59,"<>No") -> 5 | D20: =COUNTIFS(Matriz!$A$5:$A$59,$A20,Matriz!F$5:F$59,"<>No") -> 3 | E20: =COUNTIFS(Matriz!$A$5:$A$59,$A20,Matriz!G$5:G$59,"<>No") -> 2 | F20: =COUNTIF(Matriz!$A$5:$A$59,$A20) -> 5
A21: Vendedor | B21: =COUNTIFS(Matriz!$A$5:$A$59,$A21,Matriz!D$5:D$59,"<>No") -> 0 | C21: =COUNTIFS(Matriz!$A$5:$A$59,$A21,Matriz!E$5:E$59,"<>No") -> 0 | D21: =COUNTIFS(Matriz!$A$5:$A$59,$A21,Matriz!F$5:F$59,"<>No") -> 2 | E21: =COUNTIFS(Matriz!$A$5:$A$59,$A21,Matriz!G$5:G$59,"<>No") -> 0 | F21: =COUNTIF(Matriz!$A$5:$A$59,$A21) -> 2
A22: Administración | B22: =COUNTIFS(Matriz!$A$5:$A$59,$A22,Matriz!D$5:D$59,"<>No") -> 0 | C22: =COUNTIFS(Matriz!$A$5:$A$59,$A22,Matriz!E$5:E$59,"<>No") -> 0 | D22: =COUNTIFS(Matriz!$A$5:$A$59,$A22,Matriz!F$5:F$59,"<>No") -> 0 | E22: =COUNTIFS(Matriz!$A$5:$A$59,$A22,Matriz!G$5:G$59,"<>No") -> 9 | F22: =COUNTIF(Matriz!$A$5:$A$59,$A22) -> 9

Sheet Leyenda y reglas
A1: Leyenda y reglas generales
A3: Sí | B3: Permitido sin restricciones adicionales para ese rol.
A4: Propio | B4: Permitido solo sobre recursos del propio usuario (sus propiedades, visitas, conversaciones, favoritos). El backend verifica la propiedad del recurso en cada petición.
A5: Condicional | B5: Permitido solo si se cumple la condición de la columna "Condición / regla de negocio" (por ejemplo, correo verificado o conversación previa).
A6: No | B6: No permitido. El backend responde 403 (o 401 si no hay sesión).
A8: Regla 1 | B8: Los roles son acumulativos: una cuenta con rol comprador y vendedor tiene la unión de los permisos de ambas columnas.
A9: Regla 2 | B9: "Visitante" no es un rol en la base de datos: representa las rutas públicas que no exigen JWT. En la tabla Rol solo existen comprador, vendedor y administrador.
A10: Regla 3 | B10: Al cargar RolPermiso, "Propio" y "Condicional" se registran como permiso concedido; la verificación de propiedad o de la condición se implementa en el backend (middleware o servicio).
A11: Regla 4 | B11: Toda autorización se valida en el backend. Ocultar botones en el frontend mejora la experiencia, pero no protege el sistema (RNF-05, T29).
A12: Regla 5 | B12: El administrador no compra ni publica con su cuenta administrativa; si un integrante necesita hacerlo, usa otra cuenta. Así se separan funciones y la auditoría queda limpia.
A13: Regla 6 | B13: El administrador no lee conversaciones privadas. Si en el futuro se permite reportar mensajes, se agregaría un permiso específico ligado a un reporte.
A14: Regla 7 | B14: Una cuenta suspendida o inhabilitada pierde todos los permisos, aunque tenga un JWT sin expirar.
A15: Por decidir | B15: "Aprobar publicaciones" (RF-26, T33): si toda publicación debe aprobarse antes de verse, Propiedad necesita el estado "pendiente de revisión". Si solo se revisan las reportadas, las publicaciones se ven de inmediato.
A16: Por decidir | B16: "Guardar búsqueda y alertas" (RF-28) no tiene HU ni tarea asignada en el backlog actual.
